Workbook

Sheet 보관장
A1: 상품코드 | B1: 상품명 | C1: 고정로케이션 | D1: 구간 | E1: 보관장
A2: 115456 | B2: 천하)골든씨씨쉘250g | C2: 1A1-01-1-1 | D2: =LEFT(C2,6) -> 1A1-01 | E2: =VLOOKUP(D2,[1]보관장구역!$A:$B,2,0) -> 라면
A3: 132526 | B3: 농심)사천짜파게티봉지 | C3: 1A1-01-1-2 | D3: =LEFT(C3,6) -> 1A1-01 | E3: =VLOOKUP(D3,[1]보관장구역!$A:$B,2,0) -> 라면
A4: 132142 | B4: 농심)신라면120g | C4: 1A1-01-1-3 | D4: =LEFT(C4,6) -> 1A1-01 | E4: =VLOOKUP(D4,[1]보관장구역!$A:$B,2,0) -> 라면
A5: 122823 | B5: 삼양사)상쾌환스틱ZERO18g(납작복숭 | C5: 1A1-01-1-4 | D5: =LEFT(C5,6) -> 1A1-01 | E5: =VLOOKUP(D5,[1]보관장구역!$A:$B,2,0) -> 라면
A6: 132173 | B6: 농심)짜파게티봉지 | C6: 1A1-02-1-1 | D6: =LEFT(C6,6) -> 1A1-02 | E6: =VLOOKUP(D6,[1]보관장구역!$A:$B,2,0) -> 라면
A7: 132146 | B7: 농심)오징어짬뽕봉지 | C7: 1A1-02-1-2 | D7: =LEFT(C7,6) -> 1A1-02 | E7: =VLOOKUP(D7,[1]보관장구역!$A:$B,2,0) -> 라면
A8: 132150 | B8: 농심)안성탕면봉지 | C8: 1A1-02-1-3 | D8: =LEFT(C8,6) -> 1A1-02 | E8: =VLOOKUP(D8,[1]보관장구역!$A:$B,2,0) -> 라면
A9: 128280 | B9: 매일)로쉐T-16 | C9: 1A1-02-1-4 | D9: =LEFT(C9,6) -> 1A1-02 | E9: =VLOOKUP(D9,[1]보관장구역!$A:$B,2,0) -> 라면
A10: 128755 | B10: 메디카)포텐+비타민아르기닌스틱2 | C10: 1A1-03-1-1 | D10: =LEFT(C10,6) -> 1A1-03 | E10: =VLOOKUP(D10,[1]보관장구역!$A:$B,2,0) -> 라면
A11: 132157 | B11: 농심)얼큰한너구리봉지 | C11: 1A1-03-1-2 | D11: =LEFT(C11,6) -> 1A1-03 | E11: =VLOOKUP(D11,[1]보관장구역!$A:$B,2,0) -> 라면
A12: 210084 | B12: 삼양)삼양라면봉지 | C12: 1A1-03-1-3 | D12: =LEFT(C12,6) -> 1A1-03 | E12: =VLOOKUP(D12,[1]보관장구역!$A:$B,2,0) -> 라면
A13: 390977 | B13: PB)new미용티슈200매*3입 | C13: 1A1-03-1-4 | D13: =LEFT(C13,6) -> 1A1-03 | E13: =VLOOKUP(D13,[1]보관장구역!$A:$B,2,0) -> 라면
... A1500: 108739 | B1500: 티젠)푸룬쏙50G | C1500: 1C2-05-4-6 | D1500: =LEFT(C1500,6) -> 1C2-05 | E1500: =VLOOKUP(D1500,[1]보관장구역!$A:$B,2,0) -> U-8
A1501: 413655 | B1501: 디벤)굿민PD고속충전기(CtoC)_H | C1501: 1C2-06-1-1 | D1501: =LEFT(C1501,6) -> 1C2-06 | E1501: K25
A1502: 413055 | B1502: 테라톤)타입C릴타입케이블_H | C1502: 1C2-06-1-2 | D1502: =LEFT(C1502,6) -> 1C2-06 | E1502: K25
A1503: 111197 | B1503: 아모레)미쟝센컬링에센스2X볼륨컬 | C1503: 1C2-06-1-4 | D1503: =LEFT(C1503,6) -> 1C2-06 | E1503: K25
A1504: 412646 | B1504: 마즈)템테이션고소한참치맛_H | C1504: 1C2-06-1-5 | D1504: =LEFT(C1504,6) -> 1C2-06 | E1504: K25
A1505: 362313 | B1505: LG)엘라스틴 러브미샴푸600ml_H | C1505: 1C2-06-1-6 | D1505: =LEFT(C1505,6) -> 1C2-06 | E1505: K25
A1506: 125277 | B1506: 크리오)대일밴드니플패치12매_H | C1506: 1C2-06-2-1 | D1506: =LEFT(C1506,6) -> 1C2-06 | E1506: K25
A1507: 391032 | B1507: LG)쏘피유기농100%무표백대형4P | C1507: 1C2-06-2-2 | D1507: =LEFT(C1507,6) -> 1C2-06 | E1507: K25
A1508: 240016 | B1508: CJ)백설부침가루500g | C1508: 1C2-06-2-3 | D1508: =LEFT(C1508,6) -> 1C2-06 | E1508: K25
A1509: 127024 | B1509: 선린)QCYT29블루투스이어폰_H | C1509: 1C2-06-2-5 | D1509: =LEFT(C1509,6) -> 1C2-06 | E1509: K25
A1510: 106295 | B1510: 하림)더미식시래기된장국350g | C1510: 1C2-06-2-6 | D1510: =LEFT(C1510,6) -> 1C2-06 | E1510: K25
A1511: 140538 | B1511: CJ)강된장보리비빔밥(컵반) | C1511: 1C2-06-3-1 | D1511: =LEFT(C1511,6) -> 1C2-06 | E1511: K25
A1512: 140877 | B1512: 오뚜기)영양닭죽285g | C1512: 1C2-06-3-2 | D1512: =LEFT(C1512,6) -> 1C2-06 | E1512: K25
... A1534: 125186 | B1534: PB)럭히밥든든미역꾹밥225g | C1534: 1C2-07-3-6 | D1534: =LEFT(C1534,6) -> 1C2-07 | E1534: K25
A1535: 109509 | B1535: 메디카)뷰티글루콜라겐부스터샷25 | C1535: 1C2-08-1-3 | D1535: =LEFT(C1535,6) -> 1C2-08 | E1535: =VLOOKUP(D1535,[1]보관장구역!$A:$B,2,0) -> U-7
A1536: 361290 | B1536: 유한양행)덴탈케어울트라치실_H | C1536: 1C2-08-1-4 | D1536: =LEFT(C1536,6) -> 1C2-08 | E1536: =VLOOKUP(D1536,[1]보관장구역!$A:$B,2,0) -> U-7
A1537: 391120 | B1537: 유한)크리넥스마이비데물티슈10 | C1537: 1C2-08-1-5 | D1537: =LEFT(C1537,6) -> 1C2-08 | E1537: =VLOOKUP(D1537,[1]보관장구역!$A:$B,2,0) -> U-7
A1538: 381450 | B1538: 신영)비너스압박올풀림방지_살구_ | C1538: 1C2-08-1-6 | D1538: =LEFT(C1538,6) -> 1C2-08 | E1538: =VLOOKUP(D1538,[1]보관장구역!$A:$B,2,0) -> U-7
A1539: 220614 | B1539: CJ)큰햇반300g | C1539: 1C2-08-2-1 | D1539: =LEFT(C1539,6) -> 1C2-08 | E1539: =VLOOKUP(D1539,[1]보관장구역!$A:$B,2,0) -> U-7
A1540: 413688 | B1540: 선린)C타입일회용배터리2000신규_H | C1540: 1C2-08-2-3 | D1540: =LEFT(C1540,6) -> 1C2-08 | E1540: =VLOOKUP(D1540,[1]보관장구역!$A:$B,2,0) -> U-7
A1541: 108660 | B1541: 비움라이트핏KF94 5입(화이트)_H | C1541: 1C2-08-2-4 | D1541: =LEFT(C1541,6) -> 1C2-08 | E1541: =VLOOKUP(D1541,[1]보관장구역!$A:$B,2,0) -> U-7
A1542: 127620 | B1542: PB)종이음료컵360ml(20입)_H | C1542: 1C2-08-2-5 | D1542: =LEFT(C1542,6) -> 1C2-08 | E1542: =VLOOKUP(D1542,[1]보관장구역!$A:$B,2,0) -> U-7
A1543: 382116 | B1543: PB)실크터치판타롱(검정)_H | C1543: 1C2-08-2-6 | D1543: =LEFT(C1543,6) -> 1C2-08 | E1543: =VLOOKUP(D1543,[1]보관장구역!$A:$B,2,0) -> U-7
A1544: 450437 | B1544: 마즈)시져쇠고기와참치100G_H | C1544: 1C2-08-3-1 | D1544: =LEFT(C1544,6) -> 1C2-08 | E1544: =VLOOKUP(D1544,[1]보관장구역!$A:$B,2,0) -> U-7
A1545: 134007 | B1545: 애경)포인트클렌징폼100g_H | C1545: 1C2-08-3-2 | D1545: =LEFT(C1545,6) -> 1C2-08 | E1545: =VLOOKUP(D1545,[1]보관장구역!$A:$B,2,0) -> U-7
A1546: 362366 | B1546: LG)페리오듀얼클린칫솔 2입_H | C1546: 1C2-08-3-3 | D1546: =LEFT(C1546,6) -> 1C2-08 | E1546: =VLOOKUP(D1546,[1]보관장구역!$A:$B,2,0) -> U-7
... A1573: 391102 | B1573: 깨끗한)디어스킨리얼모달대형14P | C1573: 1C2-09-4-5 | D1573: =LEFT(C1573,6) -> 1C2-09 | E1573: =VLOOKUP(D1573,[1]보관장구역!$A:$B,2,0) -> U-7
...
